Workbook
Name Slicer_Category: #N/A
Name Slicer_Region: #N/A

Sheet Sales by Category
A3: Row Labels | B3: Sum of Sales
A4: Electronics | B4: 11533667
A5: Home Appliances | B5: 4772299.5
A6: Furniture | B6: 4428292.1
A7: Accessories | B7: 860906.35
A8: Office Supplies | B8: 159888.15
A9: Grand Total | B9: 21755053

Sheet Sales by Region
A3: Row Labels | B3: Sum of Sales
A4: North | B4: 6020862.6
A5: West | B5: 5483411
A6: South | B6: 5418574.2
A7: East | B7: 4832205.4
A8: Grand Total | B8: 21755053

Sheet Profit by Category
A3: Row Labels | B3: Sum of Profit
A4: Electronics | B4: 2026286.7
A5: Home Appliances | B5: 840663.08
A6: Furniture | B6: 789464.62
A7: Accessories | B7: 158711.39
A8: Office Supplies | B8: 27269.59
A9: Grand Total | B9: 3842395.4

Sheet Monthly Sales Trend
A3: Row Labels | B3: Sum of Sales
A4: 2025
A5: Jan | B5: 1009257.6
A6: Feb | B6: 1871145.6
A7: Mar | B7: 2098431.6
A8: Apr | B8: 1948579.7
A9: May | B9: 2801578.9
A10: Jun | B10: 1632784.4
A11: Jul | B11: 1983762.6
A12: Aug | B12: 1596307.8
A13: Sep | B13: 2222953.8
A14: Oct | B14: 1244483.8
A15: Nov | B15: 1589828.7
A16: Dec | B16: 1755938.6
A17: Grand Total | B17: 21755053

Sheet Top 10 Products by Sales
A3: Row Labels | B3: Sum of Sales
A4: Laptop | B4: 8331554.9
A5: Air Purifier | B5: 2542349
A6: Monitor | B6: 2203194.4
A7: Desk | B7: 1484218.8
A8: Microwave | B8: 1295532
A9: Filing Cabinet | B9: 1170482.1
A10: Bookshelf | B10: 964107.5
A11: Office Chair | B11: 829412.85
A12: Coffee Maker | B12: 597762.25
A13: Headphones | B13: 534309.6
A14: Grand Total | B14: 19952923

Sheet Discount vs Profit
A3: Row Labels | B3: Sum of Profit | C3: Sum of Sales
A4: 0 | B4: 968007.67 | C4: 5368148
A5: 0.05 | B5: 979727.86 | C5: 5558703.7
A6: 0.1 | B6: 799810.12 | C6: 4718567.7
A7: 0.15 | B7: 807009.32 | C7: 4527954.2
A8: 0.2 | B8: 266220.96 | C8: 1456476.8
A9: 0.25 | B9: 21619.42 | C9: 125202.75
A10: Grand Total | B10: 3842395.4 | C10: 21755053

Sheet Dashboard
A1: RETAIL SALES & PROFIT DASHBOARD
A2: Sales Performance | November 2025
A4: TOTAL SALES | C4: TOTAL PROFIT | E4: TOTAL ORDERS | G4: PROFIT MARGIN | I4: AVERAGE ORDER VALUE
A5: =Analysis!B2 -> 21755053 | C5: =Analysis!B3 -> 3842395.3 | E5: =Analysis!B5 -> 1200 | G5: =Analysis!B6 -> 0.17662082 | I5: =Analysis!B7 -> 18129.211

Sheet Cleaned_Data
A1: Order_ID | B1: Order_Date | C1: Customer_ID | D1: Product | E1: Category | F1: Region | G1: City | H1: Quantity | I1: Unit_Price | J1: Discount | K1: Sales | L1: Profit
A2: ORD0001 | B2: 45729 | C2: CUST1088 | D2: Office Chair | E2: Furniture | F2: East | G2: Guwahati | H2: 2 | I2: 7872 | J2: 0 | K2: 15744 | L2: 1442.41
A3: ORD0002 | B3: 45807 | C3: CUST1021 | D3: Filing Cabinet | E3: Furniture | F3: West | G3: Ahmedabad | H3: 1 | I3: 12942 | J3: 0.2 | K3: 10353.6 | L3: 829.9
A4: ORD0003 | B4: 45893 | C4: CUST1015 | D4: Microwave | E4: Home Appliances | F4: South | G4: Bengaluru | H4: 1 | I4: 12297 | J4: 0.05 | K4: 11682.15 | L4: 1043.6
A5: ORD0004 | B5: 46021 | C5: CUST1021 | D5: Bookshelf | E5: Furniture | F5: South | G5: Hyderabad | H5: 2 | I5: 10128 | J5: 0 | K5: 20256 | L5: 4081.77
A6: ORD0005 | B6: 45973 | C6: CUST1092 | D6: Desk | E6: Furniture | F6: West | G6: Mumbai | H6: 2 | I6: 13937 | J6: 0 | K6: 27874 | L6: 3517.11
A7: ORD0006 | B7: 45921 | C7: CUST1002 | D7: Bookshelf | E7: Furniture | F7: West | G7: Mumbai | H7: 1 | I7: 13139 | J7: 0.05 | K7: 12482.05 | L7: 2652.49
A8: ORD0007 | B8: 45848 | C8: CUST1095 | D8: Desk | E8: Furniture | F8: South | G8: Chennai | H8: 3 | I8: 15096 | J8: 0.05 | K8: 43023.6 | L8: 11415.53
A9: ORD0008 | B9: 45909 | C9: CUST1053 | D9: Phone Holder | E9: Accessories | F9: South | G9: Hyderabad | H9: 1 | I9: 690 | J9: 0.05 | K9: 655.5 | L9: 88.01
A10: ORD0009 | B10: 45698 | C10: CUST1129 | D10: Air Purifier | E10: Home Appliances | F10: West | G10: Mumbai | H10: 1 | I10: 9479 | J10: 0 | K10: 9479 | L10: 1561
A11: ORD0010 | B11: 45820 | C11: CUST1028 | D11: Keyboard | E11: Electronics | F11: East | G11: Kolkata | H11: 3 | I11: 2436 | J11: 0.2 | K11: 5846.4 | L11: 1229
A12: ORD0011 | B12: 45690 | C12: CUST1104 | D12: Phone Holder | E12: Accessories | F12: West | G12: Pune | H12: 1 | I12: 673 | J12: 0.05 | K12: 639.35 | L12: 144.44
A13: ORD0012 | B13: 45758 | C13: CUST1142 | D13: Keyboard | E13: Electronics | F13: North | G13: Chandigarh | H13: 5 | I13: 3092 | J13: 0.15 | K13: 13141 | L13: 1671.5
... A146: ORD0145 | B146: 46017 | C146: CUST1070 | D146: Air Purifier | E146: Home Appliances | F146: North | G146: Delhi | H146: 1 | I146: 16510 | J146: 0.1 | K146: 14859 | L146: 3506.26
A147: ORD0146 | B147: 45881 | D147: Bookshelf | E147: Furniture | F147: South | G147: Bengaluru | H147: 3 | I147: 8225 | J147: 0 | K147: 24675 | L147: 5693.5
A148: ORD0147 | B148: 45981 | C148: CUST1022 | D148: Phone Holder | E148: Accessories | F148: West | G148: Pune | H148: 1 | I148: 1150 | J148: 0 | K148: 1150 | L148: 225.9
A149: ORD0148 | B149: 45927 | C149: CUST1125 | D149: Coffee Maker | E149: Home Appliances | F149: South | G149: Chennai | H149: 5 | I149: 9767 | J149: 0.15 | K149: 41509.75 | L149: 4400.75
A150: ORD0149 | B150: 45791 | C150: CUST1174 | D150: Office Chair | E150: Furniture | F150: East | G150: Kolkata | H150: 1 | I150: 15825 | J150: 0.05 | K150: 15033.75 | L150: 1205.8
A151: ORD0150 | B151: 45696 | C151: CUST1175 | D151: Electric Kettle | E151: Home Appliances | F151: North | G151: Chandigarh | H151: 2 | I151: 3926 | J151: 0.05 | K151: 7459.4 | L151: 1849.85
A152: ORD0151 | B152: 45852 | C152: CUST1101 | D152: Notebook | E152: Office Supplies | F152: East | G152: Guwahati | H152: 5 | I152: 136 | J152: 0.05 | K152: 646 | L152: 173.6
A153: ORD0152 | B153: 45914 | C153: CUST1025 | D153: Microwave | E153: Home Appliances | F153: East | G153: Kolkata | H153: 1 | I153: 14693 | J153: 0.15 | K153: 12489.05 | L153: 1499.58
A154: ORD0153 | B154: 45729 | C154: CUST1027 | D154: Notebook | E154: Office Supplies | F154: East | G154: Guwahati | H154: 1 | I154: 155 | J154: 0 | K154: 155 | L154: 17.16
A155: ORD0154 | B155: 46006 | C155: CUST1046 | D155: Phone Holder | E155: Accessories | F155: East | G155: Guwahati | H155: 1 | I155: 339 | J155: 0.2 | K155: 271.2 | L155: 55.14
A156: ORD0155 | B156: 45930 | C156: CUST1063 | D156: Microwave | E156: Home Appliances | F156: South | G156: Hyderabad | H156: 2 | I156: 8970 | J156: 0.1 | K156: 16146 | L156: 2019.99
A157: ORD0156 | B157: 46001 | C157: CUST1064 | D157: Air Purifier | E157: Home Appliances | F157: North | G157: Jaipur | H157: 2 | I157: 21765 | J157: 0 | K157: 43530 | L157: 7527.2
A158: ORD0157 | B158: 45689 | C158: CUST1011 | D158: Bookshelf | E158: Furniture | F158: East | G158: Bhubaneswar | H158: 2 | I158: 11692 | J158: 0.2 | K158: 18707.2 | L158: 4893.13
A159: ORD0158 | B159: 45733 | C159: CUST1148 | D159: Electric Kettle | E159: Home Appliances | F159: North | G159: Delhi | H159: 5 | I159: 1670 | J159: 0.1 | K159: 7515 | L159: 1530.29
... A276: ORD0275 | B276: 45991 | C276: CUST1105 | D276: Bookshelf | E276: Furniture | F276: North | G276: Chandigarh | H276: 3 | I276: 4957 | J276: 0.2 | K276: 11896.8 | L276: 2979.59
A277: ORD0276 | B277: 45912 | C277: CUST1035 | D277: Desk | E277: Furniture | F277: North | H277: 1 | I277: 11311 | J277: 0.15 | K277: 9614.35 | L277: 835.81
A278: ORD0277 | B278: 45806 | C278: CUST1137 | D278: Monitor | E278: Electronics | F278: North | G278: Chandigarh | H278: 1 | I278: 22302 | J278: 0.1 | K278: 20071.8 | L278: 2067.13
A279: ORD0278 | B279: 45665 | C279: CUST1047 | D279: Printer Paper | E279: Office Supplies | F279: South | G279: Bengaluru | H279: 2 | I279: 530 | J279: 0.05 | K279: 1007 | L279: 168.09
A280: ORD0279 | B280: 45889 | C280: CUST1055 | D280: Keyboard | E280: Electronics | F280: South | G280: Bengaluru | H280: 4 | I280: 2002 | J280: 0.15 | K280: 6806.8 | L280: 1415.28
A281: ORD0280 | B281: 45733 | C281: CUST1105 | D281: Electric Kettle | E281: Home Appliances | F281: West | G281: Pune | H281: 2 | I281: 3352 | J281: 0.2 | K281: 5363.2 | L281: 1073.34
A282: ORD0281 | B282: 45871 | C282: CUST1136 | D282: Coffee Maker | E282: Home Appliances | F282: South | G282: Chennai | H282: 1 | I282: 5214 | J282: 0.1 | K282: 4692.6 | L282: 418.25
A283: ORD0282 | B283: 45750 | C283: CUST1084 | D283: Monitor | E283: Electronics | F283: North | G283: Delhi | H283: 2 | I283: 18960 | J283: 0.05 | K283: 36024 | L283: 6105.84
A284: ORD0283 | B284: 45706 | C284: CUST1090 | D284: Headphones | E284: Electronics | F284: North | G284: Jaipur | H284: 1 | I284: 2909 | J284: 0 | K284: 2909 | L284: 295.57
A285: ORD0284 | B285: 45763 | C285: CUST1041 | D285: Air Purifier | E285: Home Appliances | F285: North | G285: Jaipur | H285: 1 | I285: 20976 | J285: 0.05 | K285: 19927.2 | L285: 1941.28
A286: ORD0285 | B286: 45840 | C286: CUST1077 | D286: Printer Paper | E286: Office Supplies | F286: East | G286: Guwahati | H286: 4 | I286: 571 | J286: 0.1 | K286: 2055.6 | L286: 572.61
A287: ORD0286 | B287: 45989 | C287: CUST1161 | D287: USB Cable | E287: Accessories | F287: North | G287: Chandigarh | H287: 4 | I287: 887 | J287: 0.05 | K287: 3370.6 | L287: 724.41
A288: ORD0287 | B288: 45665 | C288: CUST1177 | D288: Laptop Stand | E288: Accessories | F288: West | G288: Pune | H288: 4 | I288: 905 | J288: 0.1 | K288: 3258 | L288: 801.2
...

Sheet Analysis
A1: KPI | B1: Value
A2: Total Sales | B2: =SUM(Cleaned_Data!K:K) -> 21755053 | D2: B2 =SUM(Cleaned_Data!K:K)
A3: Total Profit | B3: =SUM(Cleaned_Data!L:L) -> 3842395.3 | D3: B3 =SUM(Cleaned_Data!L:L)
A4: Total Quantity | B4: =SUM(Cleaned_Data!H:H) -> 2479 | D4: B4 =SUM(Cleaned_Data!H:H)
A5: Total Orders | B5: =COUNTA(Cleaned_Data!A:A)-1 -> 1200 | D5: B5 =COUNTA(Cleaned_Data!A:A)-1
A6: Profit Margin | B6: =B3/B2 -> 0.17662082 | D6: B6 =B3/B2
A7: Average Order Value | B7: =B2/B5 -> 18129.211 | D7: B7 =B2/B5

Sheet Raw_Data
A1: Order_ID | B1: Order_Date | C1: Customer_ID | D1: Product | E1: Category | F1: Region | G1: City | H1: Quantity | I1: Unit_Price | J1: Discount | K1: Sales | L1: Profit
A2: ORD0001 | B2: 45729 | C2: CUST1088 | D2: Office Chair | E2: Furniture | F2: East | G2: Guwahati | H2: 2 | I2: 7872 | J2: 0 | K2: 15744 | L2: 1442.41
A3: ORD0002 | B3: 45807 | C3: CUST1021 | D3: Filing Cabinet | E3: Furniture | F3: West | G3: Ahmedabad | H3: 1 | I3: 12942 | J3: 0.2 | K3: 10353.6 | L3: 829.9
A4: ORD0003 | B4: 45893 | C4: CUST1015 | D4: Microwave | E4: Home Appliances | F4: South | G4: Bengaluru | H4: 1 | I4: 12297 | J4: 0.05 | K4: 11682.15 | L4: 1043.6
A5: ORD0004 | B5: 46021 | C5: CUST1021 | D5: Bookshelf | E5: Furniture | F5: South | G5: Hyderabad | H5: 2 | I5: 10128 | J5: 0 | K5: 20256 | L5: 4081.77
A6: ORD0005 | B6: 45973 | C6: CUST1092 | D6: Desk | E6: Furniture | F6: West | G6: Mumbai | H6: 2 | I6: 13937 | J6: 0 | K6: 27874 | L6: 3517.11
A7: ORD0006 | B7: 45921 | C7: CUST1002 | D7: Bookshelf | E7: Furniture | F7: West | G7: Mumbai | H7: 1 | I7: 13139 | J7: 0.05 | K7: 12482.05 | L7: 2652.49
A8: ORD0007 | B8: 45848 | C8: CUST1095 | D8: Desk | E8: Furniture | F8: South | G8: Chennai | H8: 3 | I8: 15096 | J8: 0.05 | K8: 43023.6 | L8: 11415.53
A9: ORD0008 | B9: 45909 | C9: CUST1053 | D9: Phone Holder | E9: Accessories | F9: South | G9: Hyderabad | H9: 1 | I9: 690 | J9: 0.05 | K9: 655.5 | L9: 88.01
A10: ORD0009 | B10: 45698 | C10: CUST1129 | D10: Air Purifier | E10: Home Appliances | F10: West | G10: Mumbai | H10: 1 | I10: 9479 | J10: 0 | K10: 9479 | L10: 1561
A11: ORD0010 | B11: 45820 | C11: CUST1028 | D11: Keyboard | E11: Electronics | F11: East | G11: Kolkata | H11: 3 | I11: 2436 | J11: 0.2 | K11: 5846.4 | L11: 1229
A12: ORD0011 | B12: 45690 | C12: CUST1104 | D12: Phone Holder | E12: Accessories | F12: West | G12: Pune | H12: 1 | I12: 673 | J12: 0.05 | K12: 639.35 | L12: 144.44
A13: ORD0012 | B13: 45758 | C13: CUST1142 | D13: Keyboard | E13: Electronics | F13: North | G13: Chandigarh | H13: 5 | I13: 3092 | J13: 0.15 | K13: 13141 | L13: 1671.5
... A102: ORD0101 | B102: 45806 | C102: CUST1154 | D102: Desk | E102: Furniture | F102: East | G102: Guwahati | H102: 1 | I102: 20396 | J102: 0 | K102: 20396 | L102: 4845.23
A103: ORD0102 | B103: 45747 | C103: CUST1017 | D103: Bookshelf | E103: Furniture | F103: West | G103: Mumbai | H103: 4 | I103: 7790 | K103: 29602 | L103: 6734.46
A104: ORD0103 | B104: 45836 | C104: CUST1161 | D104: Coffee Maker | E104: Home Appliances | F104: West | G104: Ahmedabad | H104: 1 | I104: 6832 | J104: 0 | K104: 6832 | L104: 592.85
A105: ORD0104 | B105: 45811 | C105: CUST1177 | D105: Bookshelf | E105: Furniture | F105: East | G105: Bhubaneswar | H105: 1 | I105: 10804 | J105: 0 | K105: 10804 | L105: 2941
A106: ORD0105 | B106: 45846 | C106: CUST1179 | D106: Microwave | E106: Home Appliances | F106: West | G106: Ahmedabad | H106: 1 | I106: 9595 | J106: 0.05 | K106: 9115.25 | L106: 1453.55
A107: ORD0106 | B107: 45942 | C107: CUST1001 | D107: Keyboard | E107: Electronics | F107: South | G107: Chennai | H107: 2 | I107: 1820 | J107: 0.15 | K107: 3094 | L107: 611.04
A108: ORD0107 | B108: 45770 | C108: CUST1157 | D108: Stapler | E108: Office Supplies | F108: South | G108: Chennai | H108: 1 | I108: 380 | J108: 0 | K108: 380 | L108: 44.23
A109: ORD0108 | B109: 45819 | C109: CUST1093 | D109: Keyboard | E109: Electronics | F109: West | G109: Pune | H109: 1 | I109: 869 | J109: 0 | K109: 869 | L109: 193.96
A110: ORD0109 | B110: 45912 | C110: CUST1097 | D110: Office Chair | E110: Furniture | F110: East | G110: Guwahati | H110: 1 | I110: 7249 | J110: 0.15 | K110: 6161.65 | L110: 712.96
A111: ORD0110 | B111: 45753 | C111: CUST1165 | D111: Electric Kettle | E111: Home Appliances | F111: South | G111: Hyderabad | H111: 5 | I111: 3191 | J111: 0.15 | K111: 13561.75 | L111: 3695.98
A112: ORD0111 | B112: 45920 | C112: CUST1029 | D112: Monitor | E112: Electronics | F112: East | G112: Bhubaneswar | H112: 3 | I112: 22570 | J112: 0 | K112: 67710 | L112: 17285.61
A113: ORD0112 | B113: 45854 | C113: CUST1140 | D113: Desk | E113: Furniture | F113: North | G113: Chandigarh | H113: 1 | I113: 11670 | J113: 0.05 | K113: 11086.5 | L113: 2195.78
A114: ORD0113 | B114: 45883 | C114: CUST1081 | D114: USB Cable | E114: Accessories | F114: South | G114: Chennai | H114: 4 | I114: 459 | J114: 0.25 | K114: 1377 | L114: 324.91
A115: ORD0114 | B115: 45872 | C115: CUST1040 | D115: Phone Holder | E115: Accessories | F115: East | G115: Bhubaneswar | H115: 3 | I115: 810 | J115: 0 | K115: 2430 | L115: 324.98
... A146: ORD0145 | B146: 46017 | C146: CUST1070 | D146: Air Purifier | E146: Home Appliances | F146: North | G146: Delhi | H146: 1 | I146: 16510 | J146: 0.1 | K146: 14859 | L146: 3506.26
A147: ORD0146 | B147: 45881 | D147: Bookshelf | E147: Furniture | F147: South | G147: Bengaluru | H147: 3 | I147: 8225 | J147: 0 | K147: 24675 | L147: 5693.5
A148: ORD0147 | B148: 45981 | C148: CUST1022 | D148: Phone Holder | E148: Accessories | F148: West | G148: Pune | H148: 1 | I148: 1150 | J148: 0 | K148: 1150 | L148: 225.9
A149: ORD0148 | B149: 45927 | C149: CUST1125 | D149: Coffee Maker | E149: Home Appliances | F149: South | G149: Chennai | H149: 5 | I149: 9767 | J149: 0.15 | K149: 41509.75 | L149: 4400.75
A150: ORD0149 | B150: 45791 | C150: CUST1174 | D150: Office Chair | E150: Furniture | F150: East | G150: Kolkata | H150: 1 | I150: 15825 | J150: 0.05 | K150: 15033.75 | L150: 1205.8
A151: ORD0150 | B151: 45696 | C151: CUST1175 | D151: Electric Kettle | E151: Home Appliances | F151: North | G151: Chandigarh | H151: 2 | I151: 3926 | J151: 0.05 | K151: 7459.4 | L151: 1849.85
A152: ORD0151 | B152: 45852 | C152: CUST1101 | D152: Notebook | E152: Office Supplies | F152: East | G152: Guwahati | H152: 5 | I152: 136 | J152: 0.05 | K152: 646 | L152: 173.6
A153: ORD0152 | B153: 45914 | C153: CUST1025 | D153: Microwave | E153: Home Appliances | F153: East | G153: Kolkata | H153: 1 | I153: 14693 | J153: 0.15 | K153: 12489.05 | L153: 1499.58
A154: ORD0153 | B154: 45729 | C154: CUST1027 | D154: Notebook | E154: Office Supplies | F154: East | G154: Guwahati | H154: 1 | I154: 155 | J154: 0 | K154: 155 | L154: 17.16
A155: ORD0154 | B155: 46006 | C155: CUST1046 | D155: Phone Holder | E155: Accessories | F155: East | G155: Guwahati | H155: 1 | I155: 339 | J155: 0.2 | K155: 271.2 | L155: 55.14
A156: ORD0155 | B156: 45930 | C156: CUST1063 | D156: Microwave | E156: Home Appliances | F156: South | G156: Hyderabad | H156: 2 | I156: 8970 | J156: 0.1 | K156: 16146 | L156: 2019.99
A157: ORD0156 | B157: 46001 | C157: CUST1064 | D157: Air Purifier | E157: Home Appliances | F157: North | G157: Jaipur | H157: 2 | I157: 21765 | J157: 0 | K157: 43530 | L157: 7527.2
A158: ORD0157 | B158: 45689 | C158: CUST1011 | D158: Bookshelf | E158: Furniture | F158: East | G158: Bhubaneswar | H158: 2 | I158: 11692 | J158: 0.2 | K158: 18707.2 | L158: 4893.13
...

Sheet Cleaned_Data_Backup
A1: Order_ID | B1: Order_Date | C1: Customer_ID | D1: Product | E1: Category | F1: Region | G1: City | H1: Quantity | I1: Unit_Price | J1: Discount | K1: Sales | L1: Profit | M1: Product_Clean | N1: City_Clean | O1: Region_Clean | P1: Category_Clean | Q1: Category_Final | R1: Region_Final | S1: City_Final | T1: SALES_CHECK | U1: Sales_Status
A2: ORD0001 | B2: 45729 | C2: CUST1088 | D2: Office Chair | E2: Furniture | F2: East | G2: Guwahati | H2: 2 | I2: 7872 | J2: 0 | K2: 15744 | L2: 1442.41 | M2: =TRIM(D2) -> Office Chair | N2: =TRIM(G2) -> Guwahati | O2: =TRIM(F2) -> East | P2: =TRIM(E2) -> Furniture | Q2: =PROPER(E2) -> Furniture | R2: =PROPER(F2) -> East | S2: =PROPER(G2) -> Guwahati | T2: =H2*I2*(1-J2) -> 15744 | U2: =IF(ROUND(K2,2)=ROUND(T2,2),"OK","CHECK") -> OK
A3: ORD0002 | B3: 45807 | C3: CUST1021 | D3: Filing Cabinet | E3: Furniture | F3: West | G3: Ahmedabad | H3: 1 | I3: 12942 | J3: 0.2 | K3: 10353.6 | L3: 829.9 | M3: =TRIM(D3) -> Filing Cabinet | N3: =TRIM(G3) -> Ahmedabad | O3: =TRIM(F:F) -> West | P3: =TRIM(E3) -> Furniture | Q3: =PROPER(E3) -> Furniture | R3: =PROPER(F3) -> West | S3: =PROPER(G3) -> Ahmedabad | T3: =H3*I3*(1-J3) -> 10353.6 | U3: =IF(ROUND(K3,2)=ROUND(T3,2),"OK","CHECK") -> OK
A4: ORD0003 | B4: 45893 | C4: CUST1015 | D4: Microwave | E4: Home Appliances | F4: South | G4: Bengaluru | H4: 1 | I4: 12297 | J4: 0.05 | K4: 11682.15 | L4: 1043.6 | M4: =TRIM(D4) -> Microwave | N4: =TRIM(G4) -> Bengaluru | O4: =TRIM(F:F) -> South | P4: =TRIM(E4) -> Home Appliances | Q4: =PROPER(E4) -> Home Appliances | R4: =PROPER(F4) -> South | S4: =PROPER(G4) -> Bengaluru | T4: =H4*I4*(1-J4) -> 11682.15 | U4: =IF(ROUND(K4,2)=ROUND(T4,2),"OK","CHECK") -> OK
A5: ORD0004 | B5: 46021 | C5: CUST1021 | D5: Bookshelf | E5: Furniture | F5: South | G5: Hyderabad | H5: 2 | I5: 10128 | J5: 0 | K5: 20256 | L5: 4081.77 | M5: =TRIM(D5) -> Bookshelf | N5: =TRIM(G5) -> Hyderabad | O5: =TRIM(F:F) -> South | P5: =TRIM(E5) -> Furniture | Q5: =PROPER(E5) -> Furniture | R5: =PROPER(F5) -> South | S5: =PROPER(G5) -> Hyderabad | T5: =H5*I5*(1-J5) -> 20256 | U5: =IF(ROUND(K5,2)=ROUND(T5,2),"OK","CHECK") -> OK
A6: ORD0005 | B6: 45973 | C6: CUST1092 | D6: Desk | E6: Furniture | F6: West | G6: Mumbai | H6: 2 | I6: 13937 | J6: 0 | K6: 27874 | L6: 3517.11 | M6: =TRIM(D6) -> Desk | N6: =TRIM(G6) -> Mumbai | O6: =TRIM(F:F) -> West | P6: =TRIM(E6) -> Furniture | Q6: =PROPER(E6) -> Furniture | R6: =PROPER(F6) -> West | S6: =PROPER(G6) -> Mumbai | T6: =H6*I6*(1-J6) -> 27874 | U6: =IF(ROUND(K6,2)=ROUND(T6,2),"OK","CHECK") -> OK
A7: ORD0006 | B7: 45921 | C7: CUST1002 | D7: Bookshelf | E7: Furniture | F7: West | G7: Mumbai | H7: 1 | I7: 13139 | J7: 0.05 | K7: 12482.05 | L7: 2652.49 | M7: =TRIM(D7) -> Bookshelf | N7: =TRIM(G7) -> Mumbai | O7: =TRIM(F:F) -> West | P7: =TRIM(E7) -> Furniture | Q7: =PROPER(E7) -> Furniture | R7: =PROPER(F7) -> West | S7: =PROPER(G7) -> Mumbai | T7: =H7*I7*(1-J7) -> 12482.05 | U7: =IF(ROUND(K7,2)=ROUND(T7,2),"OK","CHECK") -> OK
A8: ORD0007 | B8: 45848 | C8: CUST1095 | D8: Desk | E8: Furniture | F8: South | G8: Chennai | H8: 3 | I8: 15096 | J8: 0.05 | K8: 43023.6 | L8: 11415.53 | M8: =TRIM(D8) -> Desk | N8: =TRIM(G8) -> Chennai | O8: =TRIM(F:F) -> South | P8: =TRIM(E8) -> Furniture | Q8: =PROPER(E8) -> Furniture | R8: =PROPER(F8) -> South | S8: =PROPER(G8) -> Chennai | T8: =H8*I8*(1-J8) -> 43023.6 | U8: =IF(ROUND(K8,2)=ROUND(T8,2),"OK","CHECK") -> OK
A9: ORD0008 | B9: 45909 | C9: CUST1053 | D9: Phone Holder | E9: Accessories | F9: South | G9: Hyderabad | H9: 1 | I9: 690 | J9: 0.05 | K9: 655.5 | L9: 88.01 | M9: =TRIM(D9) -> Phone Holder | N9: =TRIM(G9) -> Hyderabad | O9: =TRIM(F:F) -> South | P9: =TRIM(E9) -> Accessories | Q9: =PROPER(E9) -> Accessories | R9: =PROPER(F9) -> South | S9: =PROPER(G9) -> Hyderabad | T9: =H9*I9*(1-J9) -> 655.5 | U9: =IF(ROUND(K9,2)=ROUND(T9,2),"OK","CHECK") -> OK
A10: ORD0009 | B10: 45698 | C10: CUST1129 | D10: Air Purifier | E10: Home Appliances | F10: West | G10: Mumbai | H10: 1 | I10: 9479 | J10: 0 | K10: 9479 | L10: 1561 | M10: =TRIM(D10) -> Air Purifier | N10: =TRIM(G10) -> Mumbai | O10: =TRIM(F:F) -> West | P10: =TRIM(E10) -> Home Appliances | Q10: =PROPER(E10) -> Home Appliances | R10: =PROPER(F10) -> West | S10: =PROPER(G10) -> Mumbai | T10: =H10*I10*(1-J10) -> 9479 | U10: =IF(ROUND(K10,2)=ROUND(T10,2),"OK","CHECK") -> OK
A11: ORD0010 | B11: 45820 | C11: CUST1028 | D11: Keyboard | E11: Electronics | F11: East | G11: Kolkata | H11: 3 | I11: 2436 | J11: 0.2 | K11: 5846.4 | L11: 1229 | M11: =TRIM(D11) -> Keyboard | N11: =TRIM(G11) -> Kolkata | O11: =TRIM(F:F) -> East | P11: =TRIM(E11) -> Electronics | Q11: =PROPER(E11) -> Electronics | R11: =PROPER(F11) -> East | S11: =PROPER(G11) -> Kolkata | T11: =H11*I11*(1-J11) -> 5846.4 | U11: =IF(ROUND(K11,2)=ROUND(T11,2),"OK","CHECK") -> OK
A12: ORD0011 | B12: 45690 | C12: CUST1104 | D12: Phone Holder | E12: Accessories | F12: West | G12: Pune | H12: 1 | I12: 673 | J12: 0.05 | K12: 639.35 | L12: 144.44 | M12: =TRIM(D12) -> Phone Holder | N12: =TRIM(G12) -> Pune | O12: =TRIM(F:F) -> West | P12: =TRIM(E12) -> Accessories | Q12: =PROPER(E12) -> Accessories | R12: =PROPER(F12) -> West | S12: =PROPER(G12) -> Pune | T12: =H12*I12*(1-J12) -> 639.35 | U12: =IF(ROUND(K12,2)=ROUND(T12,2),"OK","CHECK") -> OK
A13: ORD0012 | B13: 45758 | C13: CUST1142 | D13: Keyboard | E13: Electronics | F13: North | G13: Chandigarh | H13: 5 | I13: 3092 | J13: 0.15 | K13: 13141 | L13: 1671.5 | M13: =TRIM(D13) -> Keyboard | N13: =TRIM(G13) -> Chandigarh | O13: =TRIM(F:F) -> North | P13: =TRIM(E13) -> Electronics | Q13: =PROPER(E13) -> Electronics | R13: =PROPER(F13) -> North | S13: =PROPER(G13) -> Chandigarh | T13: =H13*I13*(1-J13) -> 13141 | U13: =IF(ROUND(K13,2)=ROUND(T13,2),"OK","CHECK") -> OK
A14: ORD0013 | B14: 46003 | C14: CUST1052 | D14: Air Purifier | E14: Home Appliances | F14: East | G14: Pune | H14: 1 | I14: 8618 | J14: 0 | K14: 8618 | L14: 1786.36 | M14: =TRIM(D14) -> Air Purifier | N14: =TRIM(G14) -> Pune | O14: =TRIM(F:F) -> East | P14: =TRIM(E14) -> Home Appliances | Q14: =PROPER(E14) -> Home Appliances | R14: =PROPER(F14) -> East | S14: =PROPER(G14) -> Pune | T14: =H14*I14*(1-J14) -> 8618 | U14: =IF(ROUND(K14,2)=ROUND(T14,2),"OK","CHECK") -> OK
... A146: ORD0145 | B146: 46017 | C146: CUST1070 | D146: Air Purifier | E146: Home Appliances | F146: North | G146: Delhi | H146: 1 | I146: 16510 | J146: 0.1 | K146: 14859 | L146: 3506.26 | M146: =TRIM(D146) -> Air Purifier | N146: =TRIM(G146) -> Delhi | O146: =TRIM(F:F) -> North | P146: =TRIM(E146) -> Home Appliances | Q146: =PROPER(E146) -> Home Appliances | R146: =PROPER(F146) -> North | S146: =PROPER(G146) -> Delhi | T146: =H146*I146*(1-J146) -> 14859 | U146: =IF(ROUND(K146,2)=ROUND(T146,2),"OK","CHECK") -> OK
A147: ORD0146 | B147: 45881 | D147: Bookshelf | E147: Furniture | F147: South | G147: Bengaluru | H147: 3 | I147: 8225 | J147: 0 | K147: 24675 | L147: 5693.5 | M147: =TRIM(D147) -> Bookshelf | N147: =TRIM(G147) -> Bengaluru | O147: =TRIM(F:F) -> South | P147: =TRIM(E147) -> Furniture | Q147: =PROPER(E147) -> Furniture | R147: =PROPER(F147) -> South | S147: =PROPER(G147) -> Bengaluru | T147: =H147*I147*(1-J147) -> 24675 | U147: =IF(ROUND(K147,2)=ROUND(T147,2),"OK","CHECK") -> OK
A148: ORD0147 | B148: 45981 | C148: CUST1022 | D148: Phone Holder | E148: Accessories | F148: West | G148: Pune | H148: 1 | I148: 1150 | J148: 0 | K148: 1150 | L148: 225.9 | M148: =TRIM(D148) -> Phone Holder | N148: =TRIM(G148) -> Pune | O148: =TRIM(F:F) -> West | P148: =TRIM(E148) -> Accessories | Q148: =PROPER(E148) -> Accessories | R148: =PROPER(F148) -> West | S148: =PROPER(G148) -> Pune | T148: =H148*I148*(1-J148) -> 1150 | U148: =IF(ROUND(K148,2)=ROUND(T148,2),"OK","CHECK") -> OK
A149: ORD0148 | B149: 45927 | C149: CUST1125 | D149: Coffee Maker | E149: Home Appliances | F149: South | G149: Chennai | H149: 5 | I149: 9767 | J149: 0.15 | K149: 41509.75 | L149: 4400.75 | M149: =TRIM(D149) -> Coffee Maker | N149: =TRIM(G149) -> Chennai | O149: =TRIM(F:F) -> South | P149: =TRIM(E149) -> Home Appliances | Q149: =PROPER(E149) -> Home Appliances | R149: =PROPER(F149) -> South | S149: =PROPER(G149) -> Chennai | T149: =H149*I149*(1-J149) -> 41509.75 | U149: =IF(ROUND(K149,2)=ROUND(T149,2),"OK","CHECK") -> OK
A150: ORD0149 | B150: 45791 | C150: CUST1174 | D150: Office Chair | E150: Furniture | F150: East | G150: Kolkata | H150: 1 | I150: 15825 | J150: 0.05 | K150: 15033.75 | L150: 1205.8 | M150: =TRIM(D150) -> Office Chair | N150: =TRIM(G150) -> Kolkata | O150: =TRIM(F:F) -> East | P150: =TRIM(E150) -> Furniture | Q150: =PROPER(E150) -> Furniture | R150: =PROPER(F150) -> East | S150: =PROPER(G150) -> Kolkata | T150: =H150*I150*(1-J150) -> 15033.75 | U150: =IF(ROUND(K150,2)=ROUND(T150,2),"OK","CHECK") -> OK
A151: ORD0150 | B151: 45696 | C151: CUST1175 | D151: Electric Kettle | E151: Home Appliances | F151: North | G151: Chandigarh | H151: 2 | I151: 3926 | J151: 0.05 | K151: 7459.4 | L151: 1849.85 | M151: =TRIM(D151) -> Electric Kettle | N151: =TRIM(G151) -> Chandigarh | O151: =TRIM(F:F) -> North | P151: =TRIM(E151) -> Home Appliances | Q151: =PROPER(E151) -> Home Appliances | R151: =PROPER(F151) -> North | S151: =PROPER(G151) -> Chandigarh | T151: =H151*I151*(1-J151) -> 7459.4 | U151: =IF(ROUND(K151,2)=ROUND(T151,2),"OK","CHECK") -> OK
A152: ORD0151 | B152: 45852 | C152: CUST1101 | D152: Notebook | E152: Office Supplies | F152: East | G152: Guwahati | H152: 5 | I152: 136 | J152: 0.05 | K152: 646 | L152: 173.6 | M152: =TRIM(D152) -> Notebook | N152: =TRIM(G152) -> Guwahati | O152: =TRIM(F:F) -> East | P152: =TRIM(E152) -> Office Supplies | Q152: =PROPER(E152) -> Office Supplies | R152: =PROPER(F152) -> East | S152: =PROPER(G152) -> Guwahati | T152: =H152*I152*(1-J152) -> 646 | U152: =IF(ROUND(K152,2)=ROUND(T152,2),"OK","CHECK") -> OK
A153: ORD0152 | B153: 45914 | C153: CUST1025 | D153: Microwave | E153: Home Appliances | F153: East | G153: Kolkata | H153: 1 | I153: 14693 | J153: 0.15 | K153: 12489.05 | L153: 1499.58 | M153: =TRIM(D153) -> Microwave | N153: =TRIM(G153) -> Kolkata | O153: =TRIM(F:F) -> East | P153: =TRIM(E153) -> Home Appliances | Q153: =PROPER(E153) -> Home Appliances | R153: =PROPER(F153) -> East | S153: =PROPER(G153) -> Kolkata | T153: =H153*I153*(1-J153) -> 12489.05 | U153: =IF(ROUND(K153,2)=ROUND(T153,2),"OK","CHECK") -> OK
A154: ORD0153 | B154: 45729 | C154: CUST1027 | D154: Notebook | E154: Office Supplies | F154: East | G154: Guwahati | H154: 1 | I154: 155 | J154: 0 | K154: 155 | L154: 17.16 | M154: =TRIM(D154) -> Notebook | N154: =TRIM(G154) -> Guwahati | O154: =TRIM(F:F) -> East | P154: =TRIM(E154) -> Office Supplies | Q154: =PROPER(E154) -> Office Supplies | R154: =PROPER(F154) -> East | S154: =PROPER(G154) -> Guwahati | T154: =H154*I154*(1-J154) -> 155 | U154: =IF(ROUND(K154,2)=ROUND(T154,2),"OK","CHECK") -> OK
A155: ORD0154 | B155: 46006 | C155: CUST1046 | D155: Phone Holder | E155: Accessories | F155: East | G155: Guwahati | H155: 1 | I155: 339 | J155: 0.2 | K155: 271.2 | L155: 55.14 | M155: =TRIM(D155) -> Phone Holder | N155: =TRIM(G155) -> Guwahati | O155: =TRIM(F:F) -> East | P155: =TRIM(E155) -> Accessories | Q155: =PROPER(E155) -> Accessories | R155: =PROPER(F155) -> East | S155: =PROPER(G155) -> Guwahati | T155: =H155*I155*(1-J155) -> 271.2 | U155: =IF(ROUND(K155,2)=ROUND(T155,2),"OK","CHECK") -> OK
A156: ORD0155 | B156: 45930 | C156: CUST1063 | D156: Microwave | E156: Home Appliances | F156: South | G156: Hyderabad | H156: 2 | I156: 8970 | J156: 0.1 | K156: 16146 | L156: 2019.99 | M156: =TRIM(D156) -> Microwave | N156: =TRIM(G156) -> Hyderabad | O156: =TRIM(F:F) -> South | P156: =TRIM(E156) -> Home Appliances | Q156: =PROPER(E156) -> Home Appliances | R156: =PROPER(F156) -> South | S156: =PROPER(G156) -> Hyderabad | T156: =H156*I156*(1-J156) -> 16146 | U156: =IF(ROUND(K156,2)=ROUND(T156,2),"OK","CHECK") -> OK
A157: ORD0156 | B157: 46001 | C157: CUST1064 | D157: Air Purifier | E157: Home Appliances | F157: North | G157: Jaipur | H157: 2 | I157: 21765 | J157: 0 | K157: 43530 | L157: 7527.2 | M157: =TRIM(D157) -> Air Purifier | N157: =TRIM(G157) -> Jaipur | O157: =TRIM(F:F) -> North | P157: =TRIM(E157) -> Home Appliances | Q157: =PROPER(E157) -> Home Appliances | R157: =PROPER(F157) -> North | S157: =PROPER(G157) -> Jaipur | T157: =H157*I157*(1-J157) -> 43530 | U157: =IF(ROUND(K157,2)=ROUND(T157,2),"OK","CHECK") -> OK
A158: ORD0157 | B158: 45689 | C158: CUST1011 | D158: Bookshelf | E158: Furniture | F158: East | G158: Bhubaneswar | H158: 2 | I158: 11692 | J158: 0.2 | K158: 18707.2 | L158: 4893.13 | M158: =TRIM(D158) -> Bookshelf | N158: =TRIM(G158) -> Bhubaneswar | O158: =TRIM(F:F) -> East | P158: =TRIM(E158) -> Furniture | Q158: =PROPER(E158) -> Furniture | R158: =PROPER(F158) -> East | S158: =PROPER(G158) -> Bhubaneswar | T158: =H158*I158*(1-J158) -> 18707.2 | U158: =IF(ROUND(K158,2)=ROUND(T158,2),"OK","CHECK") -> OK
A159: ORD0158 | B159: 45733 | C159: CUST1148 | D159: Electric Kettle | E159: Home Appliances | F159: North | G159: Delhi | H159: 5 | I159: 1670 | J159: 0.1 | K159: 7515 | L159: 1530.29 | M159: =TRIM(D159) -> Electric Kettle | N159: =TRIM(G159) -> Delhi | O159: =TRIM(F:F) -> North | P159: =TRIM(E159) -> Home Appliances | Q159: =PROPER(E159) -> Home Appliances | R159: =PROPER(F159) -> North | S159: =PROPER(G159) -> Delhi | T159: =H159*I159*(1-J159) -> 7515 | U159: =IF(ROUND(K159,2)=ROUND(T159,2),"OK","CHECK") -> OK
... A276: ORD0275 | B276: 45991 | C276: CUST1105 | D276: Bookshelf | E276: Furniture | F276: North | G276: Chandigarh | H276: 3 | I276: 4957 | J276: 0.2 | K276: 11896.8 | L276: 2979.59 | M276: =TRIM(D276) -> Bookshelf | N276: =TRIM(G276) -> Chandigarh | O276: =TRIM(F:F) -> North | P276: =TRIM(E276) -> Furniture | Q276: =PROPER(E276) -> Furniture | R276: =PROPER(F276) -> North | S276: =PROPER(G276) -> Chandigarh | T276: =H276*I276*(1-J276) -> 11896.8 | U276: =IF(ROUND(K276,2)=ROUND(T276,2),"OK","CHECK") -> OK
A277: ORD0276 | B277: 45912 | C277: CUST1035 | D277: Desk | E277: Furniture | F277: North | H277: 1 | I277: 11311 | J277: 0.15 | K277: 9614.35 | L277: 835.81 | M277: =TRIM(D277) -> Desk | N277: =TRIM(G277) | O277: =TRIM(F:F) -> North | P277: =TRIM(E277) -> Furniture | Q277: =PROPER(E277) -> Furniture | R277: =PROPER(F277) -> North | S277: =PROPER(G277) | T277: =H277*I277*(1-J277) -> 9614.35 | U277: =IF(ROUND(K277,2)=ROUND(T277,2),"OK","CHECK") -> OK
A278: ORD0277 | B278: 45806 | C278: CUST1137 | D278: Monitor | E278: Electronics | F278: North | G278: Chandigarh | H278: 1 | I278: 22302 | J278: 0.1 | K278: 20071.8 | L278: 2067.13 | M278: =TRIM(D278) -> Monitor | N278: =TRIM(G278) -> Chandigarh | O278: =TRIM(F:F) -> North | P278: =TRIM(E278) -> Electronics | Q278: =PROPER(E278) -> Electronics | R278: =PROPER(F278) -> North | S278: =PROPER(G278) -> Chandigarh | T278: =H278*I278*(1-J278) -> 20071.8 | U278: =IF(ROUND(K278,2)=ROUND(T278,2),"OK","CHECK") -> OK
A279: ORD0278 | B279: 45665 | C279: CUST1047 | D279: Printer Paper | E279: Office Supplies | F279: South | G279: Bengaluru | H279: 2 | I279: 530 | J279: 0.05 | K279: 1007 | L279: 168.09 | M279: =TRIM(D279) -> Printer Paper | N279: =TRIM(G279) -> Bengaluru | O279: =TRIM(F:F) -> South | P279: =TRIM(E279) -> Office Supplies | Q279: =PROPER(E279) -> Office Supplies | R279: =PROPER(F279) -> South | S279: =PROPER(G279) -> Bengaluru | T279: =H279*I279*(1-J279) -> 1007 | U279: =IF(ROUND(K279,2)=ROUND(T279,2),"OK","CHECK") -> OK
A280: ORD0279 | B280: 45889 | C280: CUST1055 | D280: Keyboard | E280: Electronics | F280: South | G280: Bengaluru | H280: 4 | I280: 2002 | J280: 0.15 | K280: 6806.8 | L280: 1415.28 | M280: =TRIM(D280) -> Keyboard | N280: =TRIM(G280) -> Bengaluru | O280: =TRIM(F:F) -> South | P280: =TRIM(E280) -> Electronics | Q280: =PROPER(E280) -> Electronics | R280: =PROPER(F280) -> South | S280: =PROPER(G280) -> Bengaluru | T280: =H280*I280*(1-J280) -> 6806.8 | U280: =IF(ROUND(K280,2)=ROUND(T280,2),"OK","CHECK") -> OK
A281: ORD0280 | B281: 45733 | C281: CUST1105 | D281: Electric Kettle | E281: Home Appliances | F281: West | G281: Pune | H281: 2 | I281: 3352 | J281: 0.2 | K281: 5363.2 | L281: 1073.34 | M281: =TRIM(D281) -> Electric Kettle | N281: =TRIM(G281) -> Pune | O281: =TRIM(F:F) -> West | P281: =TRIM(E281) -> Home Appliances | Q281: =PROPER(E281) -> Home Appliances | R281: =PROPER(F281) -> West | S281: =PROPER(G281) -> Pune | T281: =H281*I281*(1-J281) -> 5363.2 | U281: =IF(ROUND(K281,2)=ROUND(T281,2),"OK","CHECK") -> OK
A282: ORD0281 | B282: 45871 | C282: CUST1136 | D282: Coffee Maker | E282: Home Appliances | F282: South | G282: Chennai | H282: 1 | I282: 5214 | J282: 0.1 | K282: 4692.6 | L282: 418.25 | M282: =TRIM(D282) -> Coffee Maker | N282: =TRIM(G282) -> Chennai | O282: =TRIM(F:F) -> South | P282: =TRIM(E282) -> Home Appliances | Q282: =PROPER(E282) -> Home Appliances | R282: =PROPER(F282) -> South | S282: =PROPER(G282) -> Chennai | T282: =H282*I282*(1-J282) -> 4692.6 | U282: =IF(ROUND(K282,2)=ROUND(T282,2),"OK","CHECK") -> OK
A283: ORD0282 | B283: 45750 | C283: CUST1084 | D283: Monitor | E283: Electronics | F283: North | G283: Delhi | H283: 2 | I283: 18960 | J283: 0.05 | K283: 36024 | L283: 6105.84 | M283: =TRIM(D283) -> Monitor | N283: =TRIM(G283) -> Delhi | O283: =TRIM(F:F) -> North | P283: =TRIM(E283) -> Electronics | Q283: =PROPER(E283) -> Electronics | R283: =PROPER(F283) -> North | S283: =PROPER(G283) -> Delhi | T283: =H283*I283*(1-J283) -> 36024 | U283: =IF(ROUND(K283,2)=ROUND(T283,2),"OK","CHECK") -> OK
A284: ORD0283 | B284: 45706 | C284: CUST1090 | D284: Headphones | E284: Electronics | F284: North | G284: Jaipur | H284: 1 | I284: 2909 | J284: 0 | K284: 2909 | L284: 295.57 | M284: =TRIM(D284) -> Headphones | N284: =TRIM(G284) -> Jaipur | O284: =TRIM(F:F) -> North | P284: =TRIM(E284) -> Electronics | Q284: =PROPER(E284) -> Electronics | R284: =PROPER(F284) -> North | S284: =PROPER(G284) -> Jaipur | T284: =H284*I284*(1-J284) -> 2909 | U284: =IF(ROUND(K284,2)=ROUND(T284,2),"OK","CHECK") -> OK
A285: ORD0284 | B285: 45763 | C285: CUST1041 | D285: Air Purifier | E285: Home Appliances | F285: North | G285: Jaipur | H285: 1 | I285: 20976 | J285: 0.05 | K285: 19927.2 | L285: 1941.28 | M285: =TRIM(D285) -> Air Purifier | N285: =TRIM(G285) -> Jaipur | O285: =TRIM(F:F) -> North | P285: =TRIM(E285) -> Home Appliances | Q285: =PROPER(E285) -> Home Appliances | R285: =PROPER(F285) -> North | S285: =PROPER(G285) -> Jaipur | T285: =H285*I285*(1-J285) -> 19927.2 | U285: =IF(ROUND(K285,2)=ROUND(T285,2),"OK","CHECK") -> OK
A286: ORD0285 | B286: 45840 | C286: CUST1077 | D286: Printer Paper | E286: Office Supplies | F286: East | G286: Guwahati | H286: 4 | I286: 571 | J286: 0.1 | K286: 2055.6 | L286: 572.61 | M286: =TRIM(D286) -> Printer Paper | N286: =TRIM(G286) -> Guwahati | O286: =TRIM(F:F) -> East | P286: =TRIM(E286) -> Office Supplies | Q286: =PROPER(E286) -> Office Supplies | R286: =PROPER(F286) -> East | S286: =PROPER(G286) -> Guwahati | T286: =H286*I286*(1-J286) -> 2055.6 | U286: =IF(ROUND(K286,2)=ROUND(T286,2),"OK","CHECK") -> OK
A287: ORD0286 | B287: 45989 | C287: CUST1161 | D287: USB Cable | E287: Accessories | F287: North | G287: Chandigarh | H287: 4 | I287: 887 | J287: 0.05 | K287: 3370.6 | L287: 724.41 | M287: =TRIM(D287) -> USB Cable | N287: =TRIM(G287) -> Chandigarh | O287: =TRIM(F:F) -> North | P287: =TRIM(E287) -> Accessories | Q287: =PROPER(E287) -> Accessories | R287: =PROPER(F287) -> North | S287: =PROPER(G287) -> Chandigarh | T287: =H287*I287*(1-J287) -> 3370.6 | U287: =IF(ROUND(K287,2)=ROUND(T287,2),"OK","CHECK") -> OK
...

Sheet Project_Info
A1: Project | B1: Rows_for_cleaning | C1: Original_transactions | D1: Year | E1: Purpose
A2: NovaMart Retail Sales Intelligence | B2: 1203 | C2: 1200 | D2: 2025 | E2: Excel data cleaning, analysis, dashboard, then Power BI + SQL + AI
